<?xml version="1.0" ?>
<robot name="google_robot">
   <!--generated with mjcf_urdf_simple_converter (https://github.com/Yasu31/mjcf_urdf_simple_converter)-->

   <!-- <link name="world">
      <inertial>
         <origin xyz="0.0 0.0 0.0" rpy="0.0 0.0 0.0"/>
         <mass value="0.0"/>
         <inertia ixx="0.0" iyy="0.0" izz="0.0" ixy="0" ixz="0" iyz="0"/>
      </inertial>
   </link> -->

   <link name="base_link">
      <!-- <inertial>
         <origin xyz="-0.08549215471308093 -0.0003283566830510141 0.293693594005164" rpy="0.18410589315352854 -0.00044907516071801545 1.5704315215637985"/>
         <mass value="140.49156113631398"/>
         <inertia ixx="22.199985572044444" iyy="21.147924177009482" izz="3.1781594804057987" ixy="0" ixz="0" iyz="0"/>
      </inertial> -->
      <visual name="link_base_v">
         <origin xyz="-0.09223875360195581 -2.16194849456654e-05 0.27299190198481205" rpy="0.19114878981556016 -0.00014224676061957986 1.5707815235452554"/>
         <geometry>
            <mesh filename="package://google_robot_description/meshes/converted_link_base_v.stl"/>
         </geometry>
         <material name="white"/>
      </visual>
      <collision name="link_base_0_00">
         <origin xyz="-0.1296613167139581 0.08742954969797466 0.07848667593454184" rpy="1.5626326666896526 -0.03216163129944638 1.5843547285830248"/>
         <geometry>
            <mesh filename="package://google_robot_description/meshes/converted_link_base_0_00.stl"/>
         </geometry>
         <material name="white"/>
      </collision>
      <collision name="link_base_0_01">
         <origin xyz="-0.1296613141190887 -0.08807371157679778 0.07776313948307118" rpy="1.5627453024989477 0.023917192016621458 1.5572410540849781"/>
         <geometry>
            <mesh filename="package://google_robot_description/meshes/converted_link_base_0_01.stl"/>
         </geometry>
         <material name="white"/>
      </collision>
      <collision name="link_base_1_00">
         <origin xyz="-0.023243605560313307 -0.000913311846711107 0.22153747424739467" rpy="-2.0044603094681754 -1.5609850061274022 -2.707950056894595"/>
         <geometry>
            <mesh filename="package://google_robot_description/meshes/converted_link_base_1_00.stl"/>
         </geometry>
         <material name="white"/>
      </collision>
      <collision name="link_base_1_01">
         <origin xyz="-0.00013213843775259352 -0.003891389912020692 0.8591610100071456" rpy="0.9408405165717699 -1.5141935471744359 2.251774071927241"/>
         <geometry>
            <mesh filename="package://google_robot_description/meshes/converted_link_base_1_01.stl"/>
         </geometry>
         <material name="white"/>
      </collision>
      <collision name="link_base_1_02">
         <origin xyz="-0.02309503477518413 -0.004698092936603997 1.1395854136336547" rpy="1.5749189167904627 0.013772764098090917 5.6774970830675286e-05"/>
         <geometry>
            <mesh filename="package://google_robot_description/meshes/converted_link_base_1_02.stl"/>
         </geometry>
         <material name="white"/>
      </collision>
      <collision name="link_base_1_03">
         <origin xyz="1.4284385260595886e-10 -0.001732618755265506 0.42026923811736827" rpy="0.0 -0.004122666648090467 1.5707963267948966"/>
         <geometry>
            <mesh filename="package://google_robot_description/meshes/converted_link_base_1_03.stl"/>
         </geometry>
         <material name="white"/>
      </collision>
      <collision name="link_base_1_04">
         <origin xyz="-0.0002741852647968854 -0.0010611888499496107 0.25739079767900175" rpy="-1.4641199554045614 -1.5666501092801997 -1.6775814254526509"/>
         <geometry>
            <mesh filename="package://google_robot_description/meshes/converted_link_base_1_04.stl"/>
         </geometry>
         <material name="white"/>
      </collision>
      <collision name="link_base_1_05">
         <origin xyz="-0.0017959920095182186 -0.000995980366230225 0.24157156087876594" rpy="-1.2470291882138997 -1.566447701074763 -1.8946098597648362"/>
         <geometry>
            <mesh filename="package://google_robot_description/meshes/converted_link_base_1_05.stl"/>
         </geometry>
         <material name="white"/>
      </collision>
      <collision name="link_base_1_06">
         <origin xyz="-0.03048719367157649 -0.00407962015408136 0.9698067404074032" rpy="1.5921372866823231 -1.491821254730076 -0.020966884214348447"/>
         <geometry>
            <mesh filename="package://google_robot_description/meshes/converted_link_base_1_06.stl"/>
         </geometry>
         <material name="white"/>
      </collision>
      <collision name="link_base_1_07">
         <origin xyz="-0.024516331446952998 -0.004282342006408316 1.0236903264230999" rpy="-0.26080190791992097 -0.006573526482474001 1.5838030739791051"/>
         <geometry>
            <mesh filename="package://google_robot_description/meshes/converted_link_base_1_07.stl"/>
         </geometry>
         <material name="white"/>
      </collision>
      <collision name="link_base_1_08">
         <origin xyz="0.05279125870748729 -0.005223569969948061 0.9992588696439293" rpy="-0.022219446384517928 0.27923102687212653 -1.734723475976807e-18"/>
         <geometry>
            <mesh filename="package://google_robot_description/meshes/converted_link_base_1_08.stl"/>
         </geometry>
         <material name="white"/>
      </collision>
      <collision name="link_base_1_09">
         <origin xyz="-0.05039927577855595 -0.0046188373226951455 1.12035908270126" rpy="0.004124849402150095 0.03167508524604057 0.00013065088534363386"/>
         <geometry>
            <mesh filename="package://google_robot_description/meshes/converted_link_base_1_09.stl"/>
         </geometry>
         <material name="white"/>
      </collision>
      <collision name="link_base_1_10">
         <origin xyz="0.019550870209108315 -0.004443240873268934 1.0769948939788907" rpy="-3.127515164395966 -1.290480329375801 -0.01332292395367296"/>
         <geometry>
            <mesh filename="package://google_robot_description/meshes/converted_link_base_1_10.stl"/>
         </geometry>
         <material name="white"/>
      </collision>
      <collision name="link_base_1_11">
         <origin xyz="-0.00608546585875073 -0.0019305184453416704 0.917104103053469" rpy="0.8958481424978622 -1.5528600525721117 2.2735748484621423"/>
         <geometry>
            <mesh filename="package://google_robot_description/meshes/converted_link_base_1_11.stl"/>
         </geometry>
         <material name="white"/>
      </collision>
      <collision name="link_base_1_12">
         <origin xyz="-0.02279777625955035 -0.0036121401841248597 0.93173598317525" rpy="-1.5347047542974925 -1.5107853240034956 -3.13026982507934"/>
         <geometry>
            <mesh filename="package://google_robot_description/meshes/converted_link_base_1_12.stl"/>
         </geometry>
         <material name="white"/>
      </collision>
      <collision name="link_base_1_13">
         <origin xyz="-0.02840924238956474 -0.003905612482536215 0.9484767762393416" rpy="-1.7390995260863498 -1.546450607750769 -2.9709354607748333"/>
         <geometry>
            <mesh filename="package://google_robot_description/meshes/converted_link_base_1_13.stl"/>
         </geometry>
         <material name="white"/>
      </collision>
      <collision name="link_base_1_14">
         <origin xyz="0.07021841466895207 -0.006779204715447116 1.0388533107070694" rpy="0.0 0.0 0.0"/>
         <geometry>
            <mesh filename="package://google_robot_description/meshes/converted_link_base_1_14.stl"/>
         </geometry>
         <material name="white"/>
      </collision>
      <collision name="link_base_1_15">
         <origin xyz="-0.031233709803401313 -0.0046908556250446 1.1378281289834207" rpy="1.574919068730703 0.028250960550824766 0.00011646192931036303"/>
         <geometry>
            <mesh filename="package://google_robot_description/meshes/converted_link_base_1_15.stl"/>
         </geometry>
         <material name="white"/>
      </collision>
      <collision name="link_base_1_16">
         <origin xyz="-0.008960660517729903 -0.004695325422412281 1.1389147533742148" rpy="1.57491959479392 -0.005800372211130833 -2.3916490544895197e-05"/>
         <geometry>
            <mesh filename="package://google_robot_description/meshes/converted_link_base_1_16.stl"/>
         </geometry>
         <material name="white"/>
      </collision>
      <collision name="link_base_1_17">
         <origin xyz="-0.03915800473758921 -0.004671461104009716 1.1331248747099654" rpy="1.5749224711767043 0.045689022072876284 0.00018850809722226192"/>
         <geometry>
            <mesh filename="package://google_robot_description/meshes/converted_link_base_1_17.stl"/>
         </geometry>
         <material name="white"/>
      </collision>
      <collision name="link_base_1_18">
         <origin xyz="0.026521126765433573 -0.00467128565259663 1.133671401141913" rpy="1.5747833901377108 -0.21660656506310816 -0.0008712843250853197"/>
         <geometry>
            <mesh filename="package://google_robot_description/meshes/converted_link_base_1_18.stl"/>
         </geometry>
         <material name="white"/>
      </collision>
      <collision name="link_base_1_19">
         <origin xyz="0.057783034622311685 -0.0009008488953425035 0.21847838834502287" rpy="1.6284807259534242 -1.4992799216023573 -0.05755069950683511"/>
         <geometry>
            <mesh filename="package://google_robot_description/meshes/converted_link_base_1_19.stl"/>
         </geometry>
         <material name="white"/>
      </collision>
      <!-- <visual name="link_wheel_v">
         <origin xyz="-5.489740642117986e-20 0.18283 8.563015090875109e-19" rpy="0.0 0.0 1.5707963267948966"/>
         <geometry>
            <mesh filename="package://google_robot_description/meshes/converted_link_wheel_v.stl"/>
         </geometry>
         <material name="white"/>
      </visual>
      <visual name="link_wheel_v">
         <origin xyz="-5.489740642117986e-20 -0.18283 8.563015090875109e-19" rpy="0.0 0.0 1.5707963267948966"/>
         <geometry>
            <mesh filename="package://google_robot_description/meshes/converted_link_wheel_v.stl"/>
         </geometry>
         <material name="white"/>
      </visual> -->
      <visual name="link_head_pan_v">
         <origin xyz="0.01734790753151771 8.44039069710016e-08 1.2518710839834226" rpy="0.7102792183914598 4.605302922122689e-06 1.5708002874211906"/>
         <geometry>
            <mesh filename="package://google_robot_description/meshes/converted_link_head_pan_v.stl"/>
         </geometry>
         <material name="white"/>
      </visual>
      <collision name="link_head_pan">
         <origin xyz="0.016786564891622127 4.6002984721788605e-05 1.2516083142177832" rpy="0.7361941103384193 -0.007356367894106652 1.5797260334666345"/>
         <geometry>
            <mesh filename="package://google_robot_description/meshes/converted_link_head_pan.stl"/>
         </geometry>
         <material name="white"/>
      </collision>
      <visual name="link_head_tilt_v">
         <origin xyz="0.1317184863266883 -3.172470437313845e-09 1.2899775063112424" rpy="-1.5707963267948966 -1.552006720135865 3.141592653589793"/>
         <geometry>
            <mesh filename="package://google_robot_description/meshes/converted_link_head_tilt_v.stl"/>
         </geometry>
         <material name="white"/>
      </visual>
      <collision name="link_head_tilt">
         <origin xyz="0.13615088900957345 -2.470995414950858e-05 1.289459414259963" rpy="-1.5583176658244278 -1.5548709242993137 3.1289609458558334"/>
         <geometry>
            <mesh filename="package://google_robot_description/meshes/converted_link_head_tilt.stl"/>
         </geometry>
         <material name="white"/>
      </collision>
   </link>


   <!-- <link name="link_right_wheel">
      <visual name="link_wheel_v">
         <geometry>
            <mesh filename="package://google_robot_description/meshes/converted_link_wheel_v.stl"/>
         </geometry>
         <material name="white"/>
      </visual>
      <collision name="link_wheel_v">
         <geometry>
            <mesh filename="package://google_robot_description/meshes/converted_link_wheel_v.stl"/>
         </geometry>
         <material name="white"/>
      </collision>
   </link>
   <joint name="joint_right_wheel" type="continuous">
      <origin xyz="-5.489740642117986e-20 0.18283 8.563015090875109e-19"  rpy="0.0 0.0 1.5707963267948966"/>
      <parent link="base_link" />
      <child link="link_right_wheel" />
      <axis xyz="0 0 1" />
   </joint>

   <link name="link_left_wheel">
      <visual name="link_wheel_v">
         <geometry>
            <mesh filename="package://google_robot_description/meshes/converted_link_wheel_v.stl"/>
         </geometry>
         <material name="white"/>
      </visual>
      <collision name="link_wheel_v">
         <geometry>
            <mesh filename="package://google_robot_description/meshes/converted_link_wheel_v.stl"/>
         </geometry>
         <material name="white"/>
      </collision>
   </link>
   <joint name="joint_left_wheel" type="continuous">
      <origin xyz="-5.489740642117986e-20 -0.18283 8.563015090875109e-19" rpy="0.0 0.0 1.5707963267948966"/>
      <parent link="base_link" />
      <child link="link_left_wheel" />
      <axis xyz="0 0 1" />
   </joint> -->

   <!-- <joint type="fixed" name="world2base_link_fixed">
      <parent link="world"/>
      <child link="base_link"/>
      <origin xyz="0.0 0.0 0.06205" rpy="0.0 0.0 0.0"/>
   </joint> -->
   <link name="link_torso">
      <inertial>
         <origin xyz="0.0 0.0 0.108398" rpy="0.0 0.0 0.0"/>
         <mass value="2.46883"/>
         <inertia ixx="0.0184592" iyy="0.0154173" izz="0.0102031" ixy="0" ixz="0" iyz="0"/>
      </inertial>
      <visual name="link_torso_v">
         <origin xyz="8.658159210019836e-06 -0.02210521754429183 0.10191571454357089" rpy="0.5643664781645378 0.00030686093619070043 -8.725427772460215e-05"/>
         <geometry>
            <mesh filename="package://google_robot_description/meshes/converted_link_torso_v.stl"/>
         </geometry>
         <material name="white"/>
      </visual>
      <collision name="link_torso_00">
         <origin xyz="-4.6388655020453734e-05 -0.12794687734710203 0.11271525635608291" rpy="1.3332384960708403 -0.00186770875035136 1.568021757857159"/>
         <geometry>
            <mesh filename="package://google_robot_description/meshes/converted_link_torso_00.stl"/>
         </geometry>
         <material name="white"/>
      </collision>
      <collision name="link_torso_01">
         <origin xyz="1.3621469465993702e-05 -0.008632878579039322 0.10417039099495055" rpy="0.03613726871855304 -0.000429112235745821 -0.00570976553423614"/>
         <geometry>
            <mesh filename="package://google_robot_description/meshes/converted_link_torso_01.stl"/>
         </geometry>
         <material name="white"/>
      </collision>
   </link>
   <link name="joint_torso_jointbody">
      <inertial>
         <origin xyz="0.0 0.0 0.0" rpy="0.0 0.0 0.0"/>
         <mass value="0.001"/>
         <inertia ixx="1e-09" iyy="1e-09" izz="1e-09" ixy="0" ixz="0" iyz="0"/>
      </inertial>
   </link>
   <joint type="revolute" name="joint_torso">
      <parent link="base_link"/>
      <child link="joint_torso_jointbody"/>
      <origin xyz="0.0 0.0 0.5945" rpy="0.0 0.0 0.0"/>
      <axis xyz="0.0 0.0 1.0"/>
      <limit lower="-4.49" upper="1.35" effort="100" velocity="100"/>
   </joint>
   <joint type="fixed" name="joint_torso_offset">
      <parent link="joint_torso_jointbody"/>
      <child link="link_torso"/>
      <origin xyz="-0.0 -0.0 -0.0" rpy="0.0 0.0 0.0"/>
   </joint>
   <link name="link_shoulder">
      <inertial>
         <origin xyz="0.00108994 0.00565406 0.103479" rpy="0.0 0.0 0.0"/>
         <mass value="2.08054"/>
         <inertia ixx="0.0162136" iyy="0.0158994" izz="0.00367842" ixy="0" ixz="0" iyz="0"/>
      </inertial>
      <visual name="link_shoulder_v">
         <origin xyz="-1.8103932661482854e-05 0.012241325359719925 0.07580134200927313" rpy="0.163817179060937 0.0002837321136692772 0.0002383776990193126"/>
         <geometry>
            <mesh filename="package://google_robot_description/meshes/converted_link_shoulder_v.stl"/>
         </geometry>
         <material name="white"/>
      </visual>
      <collision name="link_shoulder">
         <origin xyz="-6.108556221681531e-05 0.012698231813022516 0.07602079196516663" rpy="0.16283179740275316 0.0024307809201369324 -0.00836521577014511"/>
         <geometry>
            <mesh filename="package://google_robot_description/meshes/converted_link_shoulder.stl"/>
         </geometry>
         <material name="white"/>
      </collision>
   </link>
   <link name="joint_shoulder_jointbody">
      <inertial>
         <origin xyz="0.0 0.0 0.0" rpy="0.0 0.0 0.0"/>
         <mass value="0.001"/>
         <inertia ixx="1e-09" iyy="1e-09" izz="1e-09" ixy="0" ixz="0" iyz="0"/>
      </inertial>
   </link>
   <joint type="revolute" name="joint_shoulder">
      <parent link="link_torso"/>
      <child link="joint_shoulder_jointbody"/>
      <origin xyz="0.0 -0.167289 0.113" rpy="0.0 0.0 0.0"/>
      <axis xyz="0.0 1.0 0.0"/>
      <limit lower="-2.66" upper="3.18" effort="100" velocity="100"/>
   </joint>
   <joint type="fixed" name="joint_shoulder_offset">
      <parent link="joint_shoulder_jointbody"/>
      <child link="link_shoulder"/>
      <origin xyz="-0.0 -0.0 -0.0" rpy="0.0 0.0 0.0"/>
   </joint>
   <link name="link_bicep">
      <inertial>
         <origin xyz="9.39565e-05 -0.0191308 0.130972" rpy="0.0 0.0 0.0"/>
         <mass value="1.3989"/>
         <inertia ixx="0.00828463" iyy="0.00826766" izz="0.00210613" ixy="0" ixz="0" iyz="0"/>
      </inertial>
      <visual name="link_bicep_v">
         <origin xyz="-5.176371048195771e-06 -0.005799848417783903 0.11442910654881332" rpy="0.12479738341574165 -0.00029317886582069796 0.001343943197481455"/>
         <geometry>
            <mesh filename="package://google_robot_description/meshes/converted_link_bicep_v.stl"/>
         </geometry>
         <material name="white"/>
      </visual>
      <collision name="link_bicep">
         <origin xyz="-2.458527277740985e-05 -0.00585676587129004 0.11441431658672646" rpy="0.12620548882837532 -6.339346588180028e-05 -0.0023400189923849513"/>
         <geometry>
            <mesh filename="package://google_robot_description/meshes/converted_link_bicep.stl"/>
         </geometry>
         <material name="white"/>
      </collision>
   </link>
   <link name="joint_bicep_jointbody">
      <inertial>
         <origin xyz="0.0 0.0 0.0" rpy="0.0 0.0 0.0"/>
         <mass value="0.001"/>
         <inertia ixx="1e-09" iyy="1e-09" izz="1e-09" ixy="0" ixz="0" iyz="0"/>
      </inertial>
   </link>
   <joint type="revolute" name="joint_bicep">
      <parent link="link_shoulder"/>
      <child link="joint_bicep_jointbody"/>
      <origin xyz="0.0 0.002289 0.215029" rpy="0.0 0.0 0.0"/>
      <axis xyz="0.0 0.0 1.0"/>
      <limit lower="-2.13" upper="3.71" effort="100" velocity="100"/>
   </joint>
   <joint type="fixed" name="joint_bicep_offset">
      <parent link="joint_bicep_jointbody"/>
      <child link="link_bicep"/>
      <origin xyz="-0.0 -0.0 -0.0" rpy="0.0 0.0 0.0"/>
   </joint>
   <link name="link_elbow">
      <inertial>
         <origin xyz="-1.2460482914821558e-05 -0.07034512399332493 0.019761574109139035" rpy="0.8852449992665434 -0.0004163718989655951 0.0010722873649248177"/>
         <mass value="2.0366235174566665"/>
         <inertia ixx="0.00529312367136757" iyy="0.005076027058695623" izz="0.002671035904881885" ixy="0" ixz="0" iyz="0"/>
      </inertial>
      <visual name="link_elbow_v">
         <origin xyz="-5.662591539588581e-05 -0.07098479015843825 0.019584608434358882" rpy="0.8938066635171974 0.00045003850329572437 0.00023259654843454936"/>
         <geometry>
            <mesh filename="package://google_robot_description/meshes/converted_link_elbow_v.stl"/>
         </geometry>
         <material name="white"/>
      </visual>
      <collision name="link_elbow">
         <origin xyz="5.7377218257743655e-05 -0.06933363577777218 0.020041405534278963" rpy="0.8697165247545069 -0.002967370920618606 0.0035492745701967143"/>
         <geometry>
            <mesh filename="package://google_robot_description/meshes/converted_link_elbow.stl"/>
         </geometry>
         <material name="white"/>
      </collision>
   </link>
   <link name="joint_elbow_jointbody">
      <inertial>
         <origin xyz="0.0 0.0 0.0" rpy="0.0 0.0 0.0"/>
         <mass value="0.001"/>
         <inertia ixx="1e-09" iyy="1e-09" izz="1e-09" ixy="0" ixz="0" iyz="0"/>
      </inertial>
   </link>
   <joint type="revolute" name="joint_elbow">
      <parent link="link_bicep"/>
      <child link="joint_elbow_jointbody"/>
      <origin xyz="1.9206e-12 -0.064 0.185036" rpy="0.0 0.0 0.0"/>
      <axis xyz="0.0 1.0 0.0"/>
      <limit lower="-2.05" upper="3.79" effort="100" velocity="100"/>
   </joint>
   <joint type="fixed" name="joint_elbow_offset">
      <parent link="joint_elbow_jointbody"/>
      <child link="link_elbow"/>
      <origin xyz="-0.0 -0.0 -0.0" rpy="0.0 0.0 0.0"/>
   </joint>
   <link name="link_forearm">
      <inertial>
         <origin xyz="5.832292895816761e-05 0.015758881640218613 0.1500808524841704" rpy="-0.08535641607957227 0.00036546090986577795 0.0026021982098882457"/>
         <mass value="2.1837204258419503"/>
         <inertia ixx="0.020184595781539732" iyy="0.020062424054538827" izz="0.001580403401830833" ixy="0" ixz="0" iyz="0"/>
      </inertial>
      <visual name="link_forearm_v">
         <origin xyz="4.907691614677735e-05 0.015059738242208373 0.1487234994357093" rpy="-0.07984665264015076 0.00036769725335483727 0.0030690120535450047"/>
         <geometry>
            <mesh filename="package://google_robot_description/meshes/converted_link_forearm_v.stl"/>
         </geometry>
         <material name="white"/>
      </visual>
      <collision name="link_forearm">
         <origin xyz="7.371869174950246e-05 0.016923042466346096 0.15234101434901862" rpy="-0.09508189553997816 0.00038443747135707973 0.0022051002238043654"/>
         <geometry>
            <mesh filename="package://google_robot_description/meshes/converted_link_forearm.stl"/>
         </geometry>
         <material name="white"/>
      </collision>
   </link>
   <link name="joint_forearm_jointbody">
      <inertial>
         <origin xyz="0.0 0.0 0.0" rpy="0.0 0.0 0.0"/>
         <mass value="0.001"/>
         <inertia ixx="1e-09" iyy="1e-09" izz="1e-09" ixy="0" ixz="0" iyz="0"/>
      </inertial>
   </link>
   <joint type="revolute" name="joint_forearm">
      <parent link="link_elbow"/>
      <child link="joint_forearm_jointbody"/>
      <origin xyz="-1.92032e-12 -0.101 0.0914359" rpy="0.0 0.0 0.0"/>
      <axis xyz="0.0 0.0 1.0"/>
      <limit lower="-2.92" upper="2.92" effort="100" velocity="100"/>
   </joint>
   <joint type="fixed" name="joint_forearm_offset">
      <parent link="joint_forearm_jointbody"/>
      <child link="link_forearm"/>
      <origin xyz="-0.0 -0.0 -0.0" rpy="0.0 0.0 0.0"/>
   </joint>
   <link name="link_wrist">
      <inertial>
         <origin xyz="-4.3268494464577274e-05 -0.009859401782402669 0.04813328836388589" rpy="0.0030972638376928208 0.3926404478687946 1.58215070937575"/>
         <mass value="1.1593935664232107"/>
         <inertia ixx="0.0024918531981882367" iyy="0.0024205083986639626" izz="0.0008785309524895034" ixy="0" ixz="0" iyz="0"/>
      </inertial>
      <visual name="link_wrist_v">
         <origin xyz="-0.00010714119985469734 -0.009930435614792869 0.0473778316410918" rpy="0.002257878085661358 0.40010835771075515 1.5794369780866666"/>
         <geometry>
            <mesh filename="package://google_robot_description/meshes/converted_link_wrist_v.stl"/>
         </geometry>
         <material name="white"/>
      </visual>
      <collision name="link_wrist">
         <origin xyz="2.9072382396185255e-05 -0.009778950364375176 0.048988902689652905" rpy="0.004189191769512046 0.3839661988994625 1.5859951422496676"/>
         <geometry>
            <mesh filename="package://google_robot_description/meshes/converted_link_wrist.stl"/>
         </geometry>
         <material name="white"/>
      </collision>
   </link>
   <link name="joint_wrist_jointbody">
      <inertial>
         <origin xyz="0.0 0.0 0.0" rpy="0.0 0.0 0.0"/>
         <mass value="0.001"/>
         <inertia ixx="1e-09" iyy="1e-09" izz="1e-09" ixy="0" ixz="0" iyz="0"/>
      </inertial>
   </link>
   <joint type="revolute" name="joint_wrist">
      <parent link="link_forearm"/>
      <child link="joint_wrist_jointbody"/>
      <origin xyz="0.0 -0.00604 0.2735" rpy="0.0 0.0 0.0"/>
      <axis xyz="0.0 1.0 0.0"/>
      <limit lower="-1.79" upper="1.79" effort="100" velocity="100"/>
   </joint>
   <joint type="fixed" name="joint_wrist_offset">
      <parent link="joint_wrist_jointbody"/>
      <child link="link_wrist"/>
      <origin xyz="-0.0 -0.0 -0.0" rpy="0.0 0.0 0.0"/>
   </joint>
   <link name="link_gripper">
      <inertial>
         <origin xyz="-3.20302e-05 0.000371384 0.0387883" rpy="0.11548383039563204 -0.054898103958796574 -0.017194400388500175"/>
         <mass value="0.41474"/>
         <inertia ixx="0.000327698" iyy="0.000308611" izz="0.000272392" ixy="0" ixz="0" iyz="0"/>
      </inertial>
      <visual name="link_gripper_v">
         <origin xyz="0.0009791244615350993 -6.901553400597978e-06 0.03379147395793672" rpy="2.467144993156652 -1.5700138907216448 0.6747134079369729"/>
         <geometry>
            <mesh filename="package://google_robot_description/meshes/converted_link_gripper_v.stl"/>
         </geometry>
         <material name="white"/>
      </visual>
      <collision name="link_gripper">
         <origin xyz="3.1393971252845154e-05 2.7678639302945324e-05 0.03429612535124843" rpy="-1.6660973516035376 -1.5436359299394005 -3.04415010886606"/>
         <geometry>
            <mesh filename="package://google_robot_description/meshes/converted_link_gripper.stl"/>
         </geometry>
         <material name="white"/>
      </collision>
   </link>
   <link name="joint_gripper_jointbody">
      <inertial>
         <origin xyz="0.0 0.0 0.0" rpy="0.0 0.0 0.0"/>
         <mass value="0.001"/>
         <inertia ixx="1e-09" iyy="1e-09" izz="1e-09" ixy="0" ixz="0" iyz="0"/>
      </inertial>
   </link>
   <joint type="revolute" name="joint_gripper">
      <parent link="link_wrist"/>
      <child link="joint_gripper_jointbody"/>
      <origin xyz="0.0 0.0060384 0.10911" rpy="0.0 0.0 0.0"/>
      <axis xyz="0.0 0.0 1.0"/>
      <limit lower="-4.49" upper="1.35" effort="100" velocity="100"/>
   </joint>
   <joint type="fixed" name="joint_gripper_offset">
      <parent link="joint_gripper_jointbody"/>
      <child link="link_gripper"/>
      <origin xyz="-0.0 -0.0 -0.0" rpy="0.0 0.0 0.0"/>
   </joint>
   <link name="link_finger_right">
      <inertial>
         <origin xyz="2.2840455907115186e-05 -0.0030783787091185353 0.04056673612563627" rpy="-0.006598859471164009 -0.30636658909237835 1.5721707948986041"/>
         <mass value="0.13578381627180497"/>
         <inertia ixx="4.037902463737934e-05" iyy="2.995347521977608e-05" izz="2.843600276244179e-05" ixy="0" ixz="0" iyz="0"/>
      </inertial>
      <visual name="link_finger_base_v">
         <origin xyz="-7.33616140933975e-06 -0.002498262124096411 0.040644071627170694" rpy="-0.002318968739103977 -0.4404086011103039 1.571916371523376"/>
         <geometry>
            <mesh filename="package://google_robot_description/meshes/converted_link_finger_base_v.stl"/>
         </geometry>
         <material name="white"/>
      </visual>
      <collision name="link_finger_base">
         <origin xyz="0.00010682141674804724 -0.00186111002322285 0.04110153948586531" rpy="1.676317163439948 -0.29734742318789964 1.5721607025000164"/>
         <geometry>
            <mesh filename="package://google_robot_description/meshes/converted_link_finger_base.stl"/>
         </geometry>
         <material name="white"/>
      </collision>
   </link>
   <link name="joint_finger_right_jointbody">
      <inertial>
         <origin xyz="0.0 0.0 0.0" rpy="0.0 0.0 0.0"/>
         <mass value="0.001"/>
         <inertia ixx="1e-09" iyy="1e-09" izz="1e-09" ixy="0" ixz="0" iyz="0"/>
      </inertial>
   </link>
   <joint type="revolute" name="joint_finger_right">
      <parent link="link_gripper"/>
      <child link="joint_finger_right_jointbody"/>
      <origin xyz="0.0 0.025 0.05886" rpy="-0.9900003380671866 0.0 0.0"/>
      <axis xyz="1.0 0.0 0.0"/>
      <limit lower="0.01" upper="1.3" effort="100" velocity="100"/>
   </joint>
   <joint type="fixed" name="joint_finger_right_offset">
      <parent link="joint_finger_right_jointbody"/>
      <child link="link_finger_right"/>
      <origin xyz="-0.0 -0.0 -0.0" rpy="0.0 0.0 0.0"/>
   </joint>
   <link name="link_finger_tip_right">
      <inertial>
         <origin xyz="8.467735008652482e-06 0.0007317520071020577 0.01921860299244254" rpy="-0.00011537466633260163 -0.03904422507491656 1.57156037902024"/>
         <mass value="0.12357188206974147"/>
         <inertia ixx="3.1920370136846716e-05" iyy="2.5981981859751873e-05" izz="1.2012287886008877e-05" ixy="0" ixz="0" iyz="0"/>
      </inertial>
      <visual name="link_finger_tip_v">
         <origin xyz="2.4539219197567825e-05 0.002120593391525503 0.017735537020326812" rpy="-0.0003110246863293753 -0.16950305152986878 1.572640061780126"/>
         <geometry>
            <mesh filename="package://google_robot_description/meshes/converted_link_finger_tip_v.stl"/>
         </geometry>
         <material name="white"/>
      </visual>
      <collision name="link_finger_tip_v">
         <origin xyz="2.4539219197567825e-05 0.002120593391525503 0.017735537020326812" rpy="-0.0003110246863293753 -0.16950305152986878 1.572640061780126"/>
         <geometry>
            <mesh filename="package://google_robot_description/meshes/converted_link_finger_tip_v.stl"/>
         </geometry>
         <material name="white"/>
      </collision>
   </link>
   <joint type="fixed" name="link_finger_right2link_finger_tip_right_fixed">
      <parent link="link_finger_right"/>
      <child link="link_finger_tip_right"/>
      <origin xyz="0.0 -0.0103567 0.0641556" rpy="0.19999999987321332 0.0 0.0"/>
   </joint>
   <link name="link_finger_left">
      <inertial>
         <origin xyz="-5.1764633234557465e-06 -0.00323475062271285 0.040454462895470514" rpy="-0.0027923384974565257 -0.34964632542102314 1.571464272863905"/>
         <mass value="0.13578381627180497"/>
         <inertia ixx="3.6596900612855905e-05" iyy="2.873887205571471e-05" izz="2.559548412921936e-05" ixy="0" ixz="0" iyz="0"/>
      </inertial>
      <visual name="link_finger_base_v">
         <origin xyz="-7.33616140933975e-06 -0.002498262124096411 0.040644071627170694" rpy="-0.002318968739103977 -0.4404086011103039 1.571916371523376"/>
         <geometry>
            <mesh filename="package://google_robot_description/meshes/converted_link_finger_base_v.stl"/>
         </geometry>
         <material name="white"/>
      </visual>
      <collision name="link_finger_base_v">
         <origin xyz="-7.33616140933975e-06 -0.002498262124096411 0.040644071627170694" rpy="-0.002318968739103977 -0.4404086011103039 1.571916371523376"/>
         <geometry>
            <mesh filename="package://google_robot_description/meshes/converted_link_finger_base_v.stl"/>
         </geometry>
         <material name="white"/>
      </collision>
   </link>
   <link name="joint_finger_left_jointbody">
      <inertial>
         <origin xyz="0.0 0.0 0.0" rpy="0.0 0.0 0.0"/>
         <mass value="0.001"/>
         <inertia ixx="1e-09" iyy="1e-09" izz="1e-09" ixy="0" ixz="0" iyz="0"/>
      </inertial>
   </link>
   <joint type="revolute" name="joint_finger_left">
      <parent link="link_gripper"/>
      <child link="joint_finger_left_jointbody"/>
      <origin xyz="0.0 -0.025 0.05886" rpy="-0.9900003380671867 0.0 3.141592653589793"/>
      <axis xyz="1.0 0.0 0.0"/>
      <limit lower="0.01" upper="1.3" effort="100" velocity="100"/>
   </joint>
   <joint type="fixed" name="joint_finger_left_offset">
      <parent link="joint_finger_left_jointbody"/>
      <child link="link_finger_left"/>
      <origin xyz="-0.0 -0.0 -0.0" rpy="0.0 0.0 0.0"/>
   </joint>
   <link name="link_finger_tip_left">
      <inertial>
         <origin xyz="6.103155794239577e-06 0.0007130036641069334 0.018805950962342242" rpy="0.0003516229916379343 -0.04350750194822095 1.571497686153129"/>
         <mass value="0.12357188206974147"/>
         <inertia ixx="3.334732169925333e-05" iyy="2.6720793445485545e-05" izz="1.2736045379917187e-05" ixy="0" ixz="0" iyz="0"/>
      </inertial>
      <visual name="link_finger_tip_v">
         <origin xyz="2.4539219197567825e-05 0.002120593391525503 0.017735537020326812" rpy="-0.0003110246863293753 -0.16950305152986878 1.572640061780126"/>
         <geometry>
            <mesh filename="package://google_robot_description/meshes/converted_link_finger_tip_v.stl"/>
         </geometry>
         <material name="white"/>
      </visual>
      <collision name="link_finger_tip">
         <origin xyz="6.487081955473115e-06 0.001977461091813616 0.014585187463334232" rpy="0.01110725458533346 -0.1642177635448201 1.5726373780875196"/>
         <geometry>
            <mesh filename="package://google_robot_description/meshes/converted_link_finger_tip.stl"/>
         </geometry>
         <material name="white"/>
      </collision>
   </link>
   <joint type="fixed" name="link_finger_left2link_finger_tip_left_fixed">
      <parent link="link_finger_left"/>
      <child link="link_finger_tip_left"/>
      <origin xyz="0.0 -0.0103567 0.0641556" rpy="0.19999999987321332 0.0 0.0"/>
   </joint>
   <material name="white">
      <color rgba="1 1 1 1"/>
   </material>
</robot>
